Workbook

Sheet Outputs-R
B3: Dashboard: Perpetuity Method
D6: Model Drivers Set To | F6: =Outputs!F6 -> 2 | L6: All figures in USD thousands unless stated
D9: Main Outputs 1 | L9: Selected Inputs
W10: Learner | X10: Correct | Y10: Compare
F11: Enterprise | G11: Equity | H11: Equity | W11: =Outputs!F13 -> 125713.01 | X11: =F13 -> 125713.01 | Y11: =IF(W11=0,0,IF(W11=X11,1,0)) -> 1
F12: Value | G12: Value | H12: Per Share | L12: Terminal Growth Rate | O12: ='Inputs-R'!F107 -> 0.02
F13: =Model!H488 -> 125713.01 | L13: WACC | O13: ='Inputs-R'!L84 -> 0.095866057 | S13: Learner | T13: Correct | U13: Compare | W13: Learner | X13: Correct | Y13: Compare | AA13: Learner | AB13: Correct | AC13: Compare | AE13: Learner | AF13: Correct | AG13: Compare
D14: Best Case | E14: 1 | F14: 125713.01 | G14: =Outputs!F14-$O$14 -> 157873.71 | H14: =Outputs!G14/$O$15 -> 4.6161905 | L14: Net Debt | N14: =CONCATENATE("(End of ",'Model-R'!$H$5,")") -> (End of 2022) | O14: ='Inputs-R'!L94 -> 18642 | S14: =SUM(Outputs!E14:E16) -> 6 | T14: =SUM(E14:E16) -> 6 | U14: =IF(S14=0,0,IF(S14=T14,1,0)) -> 1 | W14: =IFERROR(_xlfn.FORMULATEXT(Outputs!F14),0) -> 0 | X14: =IFERROR(_xlfn.FORMULATEXT(F14),0) -> 0 | Y14: =IF(W14=0,0,IF(W14=X14,1,0)) -> 0 | AA14: =SUM(Outputs!G14:G16) -> 333266.66 | AB14: =SUM(G14:G16) -> 333266.66 | AC14: =IF(AA14=0,0,IF(AA14=AB14,1,0)) -> 1 | AE14: =SUM(Outputs!H14:H16) -> 9.7446393 | AF14: =SUM(H14:H16) -> 9.7446393 | AG14: =IF(AE14=0,0,IF(AE14=AF14,1,0)) -> 1
D15: Base Case | E15: 2 | F15: 125713.01 | G15: =Outputs!F15-$O$14 -> 107071.01 | H15: =Outputs!G15/$O$15 -> 3.1307312 | L15: Shares Outstanding | N15: (FD 000) | O15: ='Inputs-R'!F105 -> 34200 | W15: =IFERROR(_xlfn.FORMULATEXT(Outputs!F15),0) -> 0 | X15: =IFERROR(_xlfn.FORMULATEXT(F15),0) -> 0 | Y15: =IF(W15=0,0,IF(W15=X15,1,0)) -> 0
D16: Worst Case | E16: 3 | F16: 125713.01 | G16: =Outputs!F16-$O$14 -> 68321.94 | H16: =Outputs!G16/$O$15 -> 1.9977176 | L16: Current Stock Price | N16: (US$/sh) | O16: ='Inputs-R'!F106 -> 2.23 | W16: =IFERROR(_xlfn.FORMULATEXT(Outputs!F16),0) -> 0 | X16: =IFERROR(_xlfn.FORMULATEXT(F16),0) -> 0 | Y16: =IF(W16=0,0,IF(W16=X16,1,0)) -> 0
U18: =U14 -> 1 | Y18: =IF(SUM(Y14:Y16)=3,1,0) -> 0 | AC18: =AC14 -> 1 | AG18: =AG14 -> 1
D20: Enterprise Value 1 | L20: Equity Value per Share | S20: Learner | T20: Correct | U20: Compare
S21: =Outputs!C23 -> 125713.01 | T21: =C23 -> 125713.01 | U21: =IF(S21=0,0,IF(S21=T21,1,0)) -> 1
D22: Terminal Growth Rate | L22: Terminal Growth Rate
C23: ='Model-R'!H399 -> 125713.01 | D23: =E23-0.005 -> 0.01 | E23: =F23-0.005 -> 0.015 | F23: ='Inputs-R'!$F$107 -> 0.02 | G23: =F23+0.005 -> 0.025 | H23: =G23+0.005 -> 0.03 | L23: =D23 -> 0.01 | M23: =E23 -> 0.015 | N23: =F23 -> 0.02 | O23: =G23 -> 0.025 | P23: =H23 -> 0.03 | S23: Learner | Y23: Correct | AE23: Compare
B24: WACC | C24: =C25-0.01 -> 0.075866057 | D24: 125713.01 | E24: 125713.01 | F24: 125713.01 | G24: 125713.01 | H24: 125713.01 | J24: WACC | K24: =C24 -> 0.075866057 | L24: =Outputs!D37/$O$15 -> 3.1307312 | M24: =Outputs!E37/$O$15 -> 3.1307312 | N24: =Outputs!F37/$O$15 -> 3.1307312 | O24: =Outputs!G37/$O$15 -> 3.1307312 | P24: =Outputs!H37/$O$15 -> 3.1307312 | S24: =IFERROR(_xlfn.FORMULATEXT(Outputs!D24),0) -> 0 | T24: =IFERROR(_xlfn.FORMULATEXT(Outputs!E24),0) -> 0 | U24: =IFERROR(_xlfn.FORMULATEXT(Outputs!F24),0) -> 0 | V24: =IFERROR(_xlfn.FORMULATEXT(Outputs!G24),0) -> 0 | W24: =IFERROR(_xlfn.FORMULATEXT(Outputs!H24),0) -> 0 | Y24: =IFERROR(_xlfn.FORMULATEXT(D24),0) -> 0 | Z24: =IFERROR(_xlfn.FORMULATEXT(E24),0) -> 0 | AA24: =IFERROR(_xlfn.FORMULATEXT(F24),0) -> 0 | AB24: =IFERROR(_xlfn.FORMULATEXT(G24),0) -> 0 | AC24: =IFERROR(_xlfn.FORMULATEXT(H24),0) -> 0 | AE24: =IF(S24=Y24,1,0) -> 1 | AF24: =IF(T24=Z24,1,0) -> 1 | AG24: =IF(U24=AA24,1,0) -> 1 | AH24: =IF(V24=AB24,1,0) -> 1 | AI24: =IF(W24=AC24,1,0) -> 1
C25: =C26-0.01 -> 0.085866057 | D25: 125713.01 | E25: 125713.01 | F25: 125713.01 | G25: 125713.01 | H25: 125713.01 | K25: =C25 -> 0.085866057 | L25: =Outputs!D38/$O$15 -> 3.1307312 | M25: =Outputs!E38/$O$15 -> 3.1307312 | N25: =Outputs!F38/$O$15 -> 3.1307312 | O25: =Outputs!G38/$O$15 -> 3.1307312 | P25: =Outputs!H38/$O$15 -> 3.1307312 | S25: =IFERROR(_xlfn.FORMULATEXT(Outputs!D25),0) -> 0 | T25: =IFERROR(_xlfn.FORMULATEXT(Outputs!E25),0) -> 0 | U25: =IFERROR(_xlfn.FORMULATEXT(Outputs!F25),0) -> 0 | V25: =IFERROR(_xlfn.FORMULATEXT(Outputs!G25),0) -> 0 | W25: =IFERROR(_xlfn.FORMULATEXT(Outputs!H25),0) -> 0 | Y25: =IFERROR(_xlfn.FORMULATEXT(D25),0) -> 0 | Z25: =IFERROR(_xlfn.FORMULATEXT(E25),0) -> 0 | AA25: =IFERROR(_xlfn.FORMULATEXT(F25),0) -> 0 | AB25: =IFERROR(_xlfn.FORMULATEXT(G25),0) -> 0 | AC25: =IFERROR(_xlfn.FORMULATEXT(H25),0) -> 0 | AE25: =IF(S25=Y25,1,0) -> 1 | AF25: =IF(T25=Z25,1,0) -> 1 | AG25: =IF(U25=AA25,1,0) -> 1 | AH25: =IF(V25=AB25,1,0) -> 1 | AI25: =IF(W25=AC25,1,0) -> 1
C26: ='Inputs-R'!$L$84 -> 0.095866057 | D26: 125713.01 | E26: 125713.01 | F26: 125713.01 | G26: 125713.01 | H26: 125713.01 | K26: =C26 -> 0.095866057 | L26: =Outputs!D39/$O$15 -> 3.1307312 | M26: =Outputs!E39/$O$15 -> 3.1307312 | N26: =Outputs!F39/$O$15 -> 3.1307312 | O26: =Outputs!G39/$O$15 -> 3.1307312 | P26: =Outputs!H39/$O$15 -> 3.1307312 | S26: =IFERROR(_xlfn.FORMULATEXT(Outputs!D26),0) -> 0 | T26: =IFERROR(_xlfn.FORMULATEXT(Outputs!E26),0) -> 0 | U26: =IFERROR(_xlfn.FORMULATEXT(Outputs!F26),0) -> 0 | V26: =IFERROR(_xlfn.FORMULATEXT(Outputs!G26),0) -> 0 | W26: =IFERROR(_xlfn.FORMULATEXT(Outputs!H26),0) -> 0 | Y26: =IFERROR(_xlfn.FORMULATEXT(D26),0) -> 0 | Z26: =IFERROR(_xlfn.FORMULATEXT(E26),0) -> 0 | AA26: =IFERROR(_xlfn.FORMULATEXT(F26),0) -> 0 | AB26: =IFERROR(_xlfn.FORMULATEXT(G26),0) -> 0 | AC26: =IFERROR(_xlfn.FORMULATEXT(H26),0) -> 0 | AE26: =IF(S26=Y26,1,0) -> 1 | AF26: =IF(T26=Z26,1,0) -> 1 | AG26: =IF(U26=AA26,1,0) -> 1 | AH26: =IF(V26=AB26,1,0) -> 1 | AI26: =IF(W26=AC26,1,0) -> 1
C27: =C26+0.01 -> 0.10586606 | D27: 125713.01 | E27: 125713.01 | F27: 125713.01 | G27: 125713.01 | H27: 125713.01 | K27: =C27 -> 0.10586606 | L27: =Outputs!D40/$O$15 -> 3.1307312 | M27: =Outputs!E40/$O$15 -> 3.1307312 | N27: =Outputs!F40/$O$15 -> 3.1307312 | O27: =Outputs!G40/$O$15 -> 3.1307312 | P27: =Outputs!H40/$O$15 -> 3.1307312 | S27: =IFERROR(_xlfn.FORMULATEXT(Outputs!D27),0) -> 0 | T27: =IFERROR(_xlfn.FORMULATEXT(Outputs!E27),0) -> 0 | U27: =IFERROR(_xlfn.FORMULATEXT(Outputs!F27),0) -> 0 | V27: =IFERROR(_xlfn.FORMULATEXT(Outputs!G27),0) -> 0 | W27: =IFERROR(_xlfn.FORMULATEXT(Outputs!H27),0) -> 0 | Y27: =IFERROR(_xlfn.FORMULATEXT(D27),0) -> 0 | Z27: =IFERROR(_xlfn.FORMULATEXT(E27),0) -> 0 | AA27: =IFERROR(_xlfn.FORMULATEXT(F27),0) -> 0 | AB27: =IFERROR(_xlfn.FORMULATEXT(G27),0) -> 0 | AC27: =IFERROR(_xlfn.FORMULATEXT(H27),0) -> 0 | AE27: =IF(S27=Y27,1,0) -> 1 | AF27: =IF(T27=Z27,1,0) -> 1 | AG27: =IF(U27=AA27,1,0) -> 1 | AH27: =IF(V27=AB27,1,0) -> 1 | AI27: =IF(W27=AC27,1,0) -> 1
C28: =C27+0.01 -> 0.11586606 | D28: 125713.01 | E28: 125713.01 | F28: 125713.01 | G28: 125713.01 | H28: 125713.01 | K28: =C28 -> 0.11586606 | L28: =Outputs!D41/$O$15 -> 3.1307312 | M28: =Outputs!E41/$O$15 -> 3.1307312 | N28: =Outputs!F41/$O$15 -> 3.1307312 | O28: =Outputs!G41/$O$15 -> 3.1307312 | P28: =Outputs!H41/$O$15 -> 3.1307312 | S28: =IFERROR(_xlfn.FORMULATEXT(Outputs!D28),0) -> 0 | T28: =IFERROR(_xlfn.FORMULATEXT(Outputs!E28),0) -> 0 | U28: =IFERROR(_xlfn.FORMULATEXT(Outputs!F28),0) -> 0 | V28: =IFERROR(_xlfn.FORMULATEXT(Outputs!G28),0) -> 0 | W28: =IFERROR(_xlfn.FORMULATEXT(Outputs!H28),0) -> 0 | Y28: =IFERROR(_xlfn.FORMULATEXT(D28),0) -> 0 | Z28: =IFERROR(_xlfn.FORMULATEXT(E28),0) -> 0 | AA28: =IFERROR(_xlfn.FORMULATEXT(F28),0) -> 0 | AB28: =IFERROR(_xlfn.FORMULATEXT(G28),0) -> 0 | AC28: =IFERROR(_xlfn.FORMULATEXT(H28),0) -> 0 | AE28: =IF(S28=Y28,1,0) -> 1 | AF28: =IF(T28=Z28,1,0) -> 1 | AG28: =IF(U28=AA28,1,0) -> 1 | AH28: =IF(V28=AB28,1,0) -> 1 | AI28: =IF(W28=AC28,1,0) -> 1
AE30: =IF(SUM(AE24:AI28)=25,1,0) -> 1
D33: Equity Value | L33: Premium (Discount) to Stock Price
D35: Terminal Growth Rate | L35: Terminal Growth Rate
D36: =D23 -> 0.01 | E36: =E23 -> 0.015 | F36: =F23 -> 0.02 | G36: =G23 -> 0.025 | H36: =H23 -> 0.03 | L36: =D36 -> 0.01 | M36: =E36 -> 0.015 | N36: =F36 -> 0.02 | O36: =G36 -> 0.025 | P36: =H36 -> 0.03 | W36: Learner | X36: Correct | Y36: Compare
B37: WACC | C37: =C24 -> 0.075866057 | D37: =Outputs!D24-$O$14 -> 107071.01 | E37: =Outputs!E24-$O$14 -> 107071.01 | F37: =Outputs!F24-$O$14 -> 107071.01 | G37: =Outputs!G24-$O$14 -> 107071.01 | H37: =Outputs!H24-$O$14 -> 107071.01 | J37: WACC | K37: =C37 -> 0.075866057 | L37: =Outputs!L24/$O$16-1 -> 0.40391535 | M37: =Outputs!M24/$O$16-1 -> 0.40391535 | N37: =Outputs!N24/$O$16-1 -> 0.40391535 | O37: =Outputs!O24/$O$16-1 -> 0.40391535 | P37: =Outputs!P24/$O$16-1 -> 0.40391535 | W37: =SUM(Outputs!L24:P28) -> 78.268281 | X37: =SUM(L24:P28) -> 78.268281 | Y37: =IF(W37=0,0,IF(W37=X37,1,0)) -> 1
C38: =C25 -> 0.085866057 | D38: =Outputs!D25-$O$14 -> 107071.01 | E38: =Outputs!E25-$O$14 -> 107071.01 | F38: =Outputs!F25-$O$14 -> 107071.01 | G38: =Outputs!G25-$O$14 -> 107071.01 | H38: =Outputs!H25-$O$14 -> 107071.01 | K38: =C38 -> 0.085866057 | L38: =Outputs!L25/$O$16-1 -> 0.40391535 | M38: =Outputs!M25/$O$16-1 -> 0.40391535 | N38: =Outputs!N25/$O$16-1 -> 0.40391535 | O38: =Outputs!O25/$O$16-1 -> 0.40391535 | P38: =Outputs!P25/$O$16-1 -> 0.40391535
C39: =C26 -> 0.095866057 | D39: =Outputs!D26-$O$14 -> 107071.01 | E39: =Outputs!E26-$O$14 -> 107071.01 | F39: =Outputs!F26-$O$14 -> 107071.01 | G39: =Outputs!G26-$O$14 -> 107071.01 | H39: =Outputs!H26-$O$14 -> 107071.01 | K39: =C39 -> 0.095866057 | L39: =Outputs!L26/$O$16-1 -> 0.40391535 | M39: =Outputs!M26/$O$16-1 -> 0.40391535 | N39: =Outputs!N26/$O$16-1 -> 0.40391535 | O39: =Outputs!O26/$O$16-1 -> 0.40391535 | P39: =Outputs!P26/$O$16-1 -> 0.40391535 | S39: Learner | T39: Correct | U39: Compare | W39: Learner | X39: Correct | Y39: Compare
C40: =C27 -> 0.10586606 | D40: =Outputs!D27-$O$14 -> 107071.01 | E40: =Outputs!E27-$O$14 -> 107071.01 | F40: =Outputs!F27-$O$14 -> 107071.01 | G40: =Outputs!G27-$O$14 -> 107071.01 | H40: =Outputs!H27-$O$14 -> 107071.01 | K40: =C40 -> 0.10586606 | L40: =Outputs!L27/$O$16-1 -> 0.40391535 | M40: =Outputs!M27/$O$16-1 -> 0.40391535 | N40: =Outputs!N27/$O$16-1 -> 0.40391535 | O40: =Outputs!O27/$O$16-1 -> 0.40391535 | P40: =Outputs!P27/$O$16-1 -> 0.40391535 | S40: =SUM(Outputs!D37:H41) -> 2676775.2 | T40: =SUM(D37:H41) -> 2676775.2 | U40: =IF(S40=0,0,IF(S40=T40,1,0)) -> 1 | W40: =SUM(Outputs!L37:P41) -> 10.097884 | X40: =SUM(L37:P41) -> 10.097884 | Y40: =IF(W40=0,0,IF(W40=X40,1,0)) -> 1
C41: =C28 -> 0.11586606 | D41: =Outputs!D28-$O$14 -> 107071.01 | E41: =Outputs!E28-$O$14 -> 107071.01 | F41: =Outputs!F28-$O$14 -> 107071.01 | G41: =Outputs!G28-$O$14 -> 107071.01 | H41: =Outputs!H28-$O$14 -> 107071.01 | K41: =C41 -> 0.11586606 | L41: =Outputs!L28/$O$16-1 -> 0.40391535 | M41: =Outputs!M28/$O$16-1 -> 0.40391535 | N41: =Outputs!N28/$O$16-1 -> 0.40391535 | O41: =Outputs!O28/$O$16-1 -> 0.40391535 | P41: =Outputs!P28/$O$16-1 -> 0.40391535
P43: These tables require the workbook calculation to be set to automatic to update. | S43: =IF(SUM(U18+U21+Y11+Y18+AC18+AG18+AE30+U40+Y37+Y40)=10,"COMPLETE","")
B47: Dashboard: Multiple Method
D50: Model Drivers Set To | L50: All figures in USD thousands unless stated
D53: Main Outputs 1 | L53: Selected Inputs
W54: Learner | X54: Correct | Y54: Compare
F55: Enterprise | G55: Equity | H55: Equity | W55: =Outputs!F57 -> 130862.76 | X55: =F57 -> 130862.76 | Y55: =IF(W55=0,0,IF(W55=X55,1,0)) -> 1
F56: Value | G56: Value | H56: Per Share | L56: Terminal Multiple | O56: ='Inputs-R'!$F$108 -> 7
F57: =Model!H540 -> 130862.76 | L57: WACC | O57: ='Inputs-R'!$L$84 -> 0.095866057 | S57: Learner | T57: Correct | U57: Compare | W57: Learner | X57: Correct | Y57: Compare
D58: =D14 -> Best Case | E58: 1 | F58: 130862.76 | G58: =F58-$O$58 -> 112220.76 | H58: =+G58/$O$59 -> 3.2813089 | L58: Net Debt | N58: =N14 -> (End of 2022) | O58: ='Inputs-R'!$L$94 -> 18642 | S58: =SUM(Outputs!E58:E60) -> 6 | T58: =SUM(E58:E60) -> 6 | U58: =IF(S58=0,0,IF(S58=T58,1,0)) -> 1 | W58: =IFERROR(_xlfn.FORMULATEXT(Outputs!F58),0) -> 0 | X58: =IFERROR(_xlfn.FORMULATEXT(F58),0) -> 0 | Y58: =IF(W58=0,0,IF(W58=X58,1,0)) -> 0
D59: =D15 -> Base Case | E59: 2 | F59: 130862.76 | G59: =F59-$O$58 -> 112220.76 | H59: =+G59/$O$59 -> 3.2813089 | L59: Shares Outstanding | N59: (FD 000) | O59: ='Inputs-R'!$F$105 -> 34200 | W59: =IFERROR(_xlfn.FORMULATEXT(Outputs!F59),0) -> 0 | X59: =IFERROR(_xlfn.FORMULATEXT(F59),0) -> 0 | Y59: =IF(W59=0,0,IF(W59=X59,1,0)) -> 0
D60: =D16 -> Worst Case | E60: 3 | F60: 130862.76 | G60: =F60-$O$58 -> 112220.76 | H60: =+G60/$O$59 -> 3.2813089 | L60: Current Stock Price | N60: (US$/sh) | O60: ='Inputs-R'!$F$106 -> 2.23 | W60: =IFERROR(_xlfn.FORMULATEXT(Outputs!F60),0) -> 0 | X60: =IFERROR(_xlfn.FORMULATEXT(F60),0) -> 0 | Y60: =IF(W60=0,0,IF(W60=X60,1,0)) -> 0
...

Sheet Inputs
B3: Drivers
B5: All figures in USD thousands unless stated | G5: =$F$105 -> 2023 | H5: =G5+1 -> 2024 | I5: =H5+1 -> 2025 | J5: =I5+1 -> 2026 | K5: =J5+1 -> 2027 | L5: Term
B7: Driver Switch | D7: =Outputs!F6 -> 2
B10: Revenue Growth | G10: =CHOOSE($D$7,G12,G13,G14) -> 0.03 | H10: =CHOOSE($D$7,H12,H13,H14) -> 0.02 | I10: =CHOOSE($D$7,I12,I13,I14) -> 0.02 | J10: =CHOOSE($D$7,J12,J13,J14) -> 0.015 | K10: =CHOOSE($D$7,K12,K13,K14) -> 0.015 | L10: =CHOOSE($D$7,L12,L13,L14) -> 0.01
B12: =Outputs!D14 -> Best Case | G12: 0.04 | H12: 0.03 | I12: 0.025 | J12: 0.02 | K12: 0.02 | L12: 0.015
B13: =Outputs!D15 -> Base Case | G13: 0.03 | H13: 0.02 | I13: 0.02 | J13: 0.015 | K13: 0.015 | L13: 0.01
B14: =Outputs!D16 -> Worst Case | G14: 0.01 | H14: 0.01 | I14: 0.005 | J14: 0.005 | K14: 0.005 | L14: 0.005
B17: Cost projection Increases | G17: =CHOOSE($D$7,G19,G20,G21) -> 0.035 | H17: =CHOOSE($D$7,H19,H20,H21) -> 0.03 | I17: =CHOOSE($D$7,I19,I20,I21) -> 0.03 | J17: =CHOOSE($D$7,J19,J20,J21) -> 0.025 | K17: =CHOOSE($D$7,K19,K20,K21) -> 0.025 | L17: =CHOOSE($D$7,L19,L20,L21) -> 0.015
B19: =$B$12 -> Best Case | G19: 0.035 | H19: 0.02 | I19: 0.02 | J19: 0.02 | K19: 0.015 | L19: 0.008
B20: =$B$13 -> Base Case | G20: 0.035 | H20: 0.03 | I20: 0.03 | J20: 0.025 | K20: 0.025 | L20: 0.015
B21: =$B$14 -> Worst Case | G21: 0.05 | H21: 0.04 | I21: 0.04 | J21: 0.035 | K21: 0.03 | L21: 0.03
B24: Capital Expenditure | G24: =CHOOSE($D$7,G26,G27,G28) -> 10000 | H24: =CHOOSE($D$7,H26,H27,H28) -> 8000 | I24: =CHOOSE($D$7,I26,I27,I28) -> 9000 | J24: =CHOOSE($D$7,J26,J27,J28) -> 5000 | K24: =CHOOSE($D$7,K26,K27,K28) -> 5000 | L24: =CHOOSE($D$7,L26,L27,L28) -> 6000
B26: =$B$12 -> Best Case | G26: 4000 | H26: 4300 | I26: 4400 | J26: 4600 | K26: 4800 | L26: 4900
B27: =$B$13 -> Base Case | G27: 10000 | H27: 8000 | I27: 9000 | J27: 5000 | K27: 5000 | L27: 6000
B28: =$B$14 -> Worst Case | G28: 5000 | H28: 5200 | I28: 5400 | J28: 5500 | K28: 5600 | L28: 5800
B31: Inflation Rate | G31: 0.035 | H31: 0.03 | I31: 0.03 | J31: 0.025 | K31: 0.025 | L31: 0.015
B34: Working Capital 1
B35: Accounts Receivable | E35: (Days) | G35: 45 | H35: 45 | I35: 45 | J35: 45 | K35: 45 | L35: =K35 -> 45
B36: Inventory | E36: (Days) | G36: 25 | H36: 25 | I36: 25 | J36: 25 | K36: 25 | L36: =K36 -> 25
B37: Accounts Payable | E37: (Days) | G37: 40 | H37: 40 | I37: 40 | J37: 40 | K37: 40 | L37: =K37 -> 40
B40: Other Annual Inputs
A41: - | B41: Term Debt | E41: Increase / (Decrease) | G41: -3000 | H41: -3000 | I41: -2000 | J41: -3000 | K41: -3000 | L41: -2000
B42: Common Equity | E42: Increase / (Decrease) | G42: -1000 | H42: -1000 | I42: -1000 | J42: -1000 | K42: -1000 | L42: -1000
B43: ='Inputs-R'!Q39 | L43: We have assumed working capital amounts per day in terminal year are equal to the previous year.
B47: Weighted Average Cost of Capital
B49: All figures in USD thousands unless stated
H51: Average | I51: Debt/ | J51: Debt/ | K51: Levered | L51: Unlevered
B52: Name | C52: Industry | D52: Region | E52: Market | F52: Debt | G52: Equity | H52: Tax Rate 1 | I52: Equity | J52: Capital | K52: Beta 2 | L52: Beta 3
B54: Peer 1 | C54: Industry 1 | D54: Canada | F54: 88888 | G54: 9999999 | H54: 0.315 | I54: =F54/G54 -> 0.0088888009 | J54: =F54/(F54+G54) -> 0.0088104862 | K54: 0.85 | L54: =K54/(1+(1-H54)*(I54)) -> 0.84485582
B55: Peer 2 | C55: Industry 2 | D55: USA | F55: 88888 | G55: 9999999 | H55: 0.315 | I55: =F55/G55 -> 0.0088888009 | J55: =F55/(F55+G55) -> 0.0088104862 | K55: 0.85 | L55: =K55/(1+(1-H55)*(I55)) -> 0.84485582
B56: Peer 3 | C56: Industry 3 | D56: USA | F56: 88888 | G56: 9999999 | H56: 0.315 | I56: =F56/G56 -> 0.0088888009 | J56: =F56/(F56+G56) -> 0.0088104862 | K56: 0.85 | L56: =K56/(1+(1-H56)*(I56)) -> 0.84485582
B57: Peer 4 | C57: Industry 4 | D57: USA | F57: 88888 | G57: 9999999 | H57: 0.315 | I57: =F57/G57 -> 0.0088888009 | J57: =F57/(F57+G57) -> 0.0088104862 | K57: 0.85 | L57: =K57/(1+(1-H57)*(I57)) -> 0.84485582
B58: Peer 5 | C58: Industry 5 | D58: Canada | F58: 88888 | G58: 9999999 | H58: 0.315 | I58: =F58/G58 -> 0.0088888009 | J58: =F58/(F58+G58) -> 0.0088104862 | K58: 0.85 | L58: =K58/(1+(1-H58)*(I58)) -> 0.84485582
B59: Peer 6 | C59: Industry 6 | D59: Canada | F59: 88888 | G59: 9999999 | H59: 0.315 | I59: =F59/G59 -> 0.0088888009 | J59: =F59/(F59+G59) -> 0.0088104862 | K59: 0.85 | L59: =K59/(1+(1-H59)*(I59)) -> 0.84485582
B60: Peer 7 | C60: Industry 7 | D60: USA | F60: 88888 | G60: 9999999 | H60: 0.315 | I60: =F60/G60 -> 0.0088888009 | J60: =F60/(F60+G60) -> 0.0088104862 | K60: 0.85 | L60: =K60/(1+(1-H60)*(I60)) -> 0.84485582
B61: Peer 8 | C61: Industry 8 | D61: Canada | F61: 88888 | G61: 9999999 | H61: 0.315 | I61: =F61/G61 -> 0.0088888009 | J61: =F61/(F61+G61) -> 0.0088104862 | K61: 0.85 | L61: =K61/(1+(1-H61)*(I61)) -> 0.84485582
B62: Peer 9 | C62: Industry 9 | D62: Ghana | F62: 88888 | G62: 9999999 | H62: 0.315 | I62: =F62/G62 -> 0.0088888009 | J62: =F62/(F62+G62) -> 0.0088104862 | K62: 0.99399 | L62: =K62/(1+(1-H62)*(I62)) -> 0.98797439
B63: Peer 10 | C63: Industry 10 | D63: China | F63: 88888 | G63: 9999999 | H63: 0.315 | I63: =F63/G63 -> 0.0088888009 | J63: =F63/(F63+G63) -> 0.0088104862 | K63: 0.88324 | L63: =K63/(1+(1-H63)*(I63)) -> 0.87789465
I64: ='Inputs-R'!Q51 -> 0 | J64: ='Inputs-R'!U51 -> 0 | L64: ='Inputs-R'!Y51 -> 0
G65: Average | H65: =AVERAGE(H54:H63) -> 0.315 | I65: =AVERAGE(I54:I63) -> 0.0088888009 | J65: =AVERAGE(J54:J63) -> 0.0088104862 | K65: =AVERAGE(K54:K63) -> 0.867723 | L65: =AVERAGE(L54:L63) -> 0.86247156
...

Sheet Inputs-R
B3: Drivers
B5: All figures in USD thousands unless stated | G5: =$F$97 -> 2023 | H5: =G5+1 -> 2024 | I5: =H5+1 -> 2025 | J5: =I5+1 -> 2026 | K5: =J5+1 -> 2027 | L5: Term
B7: Driver Switch | D7: ='Outputs-R'!F6 -> 2
O9: Learner | P9: Correct | Q9: Compare
B10: Sales Volume Growth | G10: {=INDEX(G12:G14,$D$7)} -> 0.02 | H10: {=INDEX(H12:H14,$D$7)} -> 0.01 | I10: {=INDEX(I12:I14,$D$7)} -> 0.01 | J10: {=INDEX(J12:J14,$D$7)} -> 0.005 | K10: {=INDEX(K12:K14,$D$7)} -> 0.005 | L10: {=INDEX(L12:L14,$D$7)} -> 0.005 | O10: =SUM(Inputs!G10:L10) -> 0.11 | P10: =SUM(G10:L10) -> 0.055 | Q10: =IF(O10=0,0,IF(O10=P10,1,0)) -> 0
B12: =Outputs!D14 -> Best Case | G12: 0.03 | H12: 0.02 | I12: 0.02 | J12: 0.015 | K12: 0.015 | L12: 0.01
B13: =Outputs!D15 -> Base Case | G13: 0.02 | H13: 0.01 | I13: 0.01 | J13: 0.005 | K13: 0.005 | L13: 0.005
B14: =Outputs!D16 -> Worst Case | G14: 0.01 | H14: 0.01 | I14: 0.005 | J14: 0.005 | K14: 0.005 | L14: 0.005
O16: Learner | P16: Correct | Q16: Compare
B17: Pricing Increases | G17: {=INDEX(G19:G21,$D$7)} -> 0.03 | H17: {=INDEX(H19:H21,$D$7)} -> 0.01 | I17: {=INDEX(I19:I21,$D$7)} -> 0.01 | J17: {=INDEX(J19:J21,$D$7)} -> 0.01 | K17: {=INDEX(K19:K21,$D$7)} -> 0.005 | L17: {=INDEX(L19:L21,$D$7)} -> 0.005 | O17: =SUM(Inputs!G17:L17) -> 0.16 | P17: =SUM(G17:L17) -> 0.07 | Q17: =IF(O17=0,0,IF(O17=P17,1,0)) -> 0
B19: =$B$12 -> Best Case | G19: 0.035 | H19: 0.02 | I19: 0.02 | J19: 0.02 | K19: 0.015 | L19: 0.008
B20: =$B$13 -> Base Case | G20: 0.03 | H20: 0.01 | I20: 0.01 | J20: 0.01 | K20: 0.005 | L20: 0.005
B21: =$B$14 -> Worst Case | G21: 0.01 | H21: 0.01 | I21: 0.005 | J21: 0.005 | K21: 0.005 | L21: 0.005
O23: Learner | P23: Correct | Q23: Compare
B24: Capital Expenditure | G24: {=INDEX(G26:G28,$D$7)} -> 4550 | H24: {=INDEX(H26:H28,$D$7)} -> 4700 | I24: {=INDEX(I26:I28,$D$7)} -> 4850 | J24: {=INDEX(J26:J28,$D$7)} -> 5000 | K24: {=INDEX(K26:K28,$D$7)} -> 5125 | L24: {=INDEX(L26:L28,$D$7)} -> 5300 | O24: =SUM(Inputs!G24:L24) -> 43000 | P24: =SUM(G24:L24) -> 29525 | Q24: =IF(O24=0,0,IF(O24=P24,1,0)) -> 0
B26: =$B$12 -> Best Case | G26: 4000 | H26: 4300 | I26: 4400 | J26: 4600 | K26: 4800 | L26: 4900
B27: =$B$13 -> Base Case | G27: 4550 | H27: 4700 | I27: 4850 | J27: 5000 | K27: 5125 | L27: 5300
B28: =$B$14 -> Worst Case | G28: 5000 | H28: 5200 | I28: 5400 | J28: 5500 | K28: 5600 | L28: 5800
B31: Inflation Rate | G31: 0.035 | H31: 0.03 | I31: 0.03 | J31: 0.025 | K31: 0.025 | L31: 0.015
B34: Working Capital 1 | O34: Learner | P34: Correct | Q34: Compare
B35: Accounts Receivable | E35: (Days) | G35: 45 | H35: 45 | I35: 45 | J35: 45 | K35: 45 | L35: =K35 -> 45 | O35: =Inputs!L35 -> 45 | P35: =L35 -> 45 | Q35: =IF(O35=0,0,IF(O35=P35,1,0)) -> 1
B36: Inventory | E36: (Days) | G36: 25 | H36: 25 | I36: 25 | J36: 25 | K36: 25 | L36: =K36 -> 25 | O36: =Inputs!L36 -> 25 | P36: =L36 -> 25 | Q36: =IF(O36=0,0,IF(O36=P36,1,0)) -> 1
B37: Accounts Payable | E37: (Days) | G37: 40 | H37: 40 | I37: 40 | J37: 40 | K37: 40 | L37: =K37 -> 40 | O37: =Inputs!L37 -> 40 | P37: =L37 -> 40 | Q37: =IF(O37=0,0,IF(O37=P37,1,0)) -> 1
Q39: =IF(SUM(Q9:Q37)=6,"COMPLETE","")
L40: We have assumed working capital amounts per day in terminal year are equal to the previous year.
B44: Weighted Average Cost of Capital
B46: All figures in USD thousands unless stated
H48: Average | I48: Debt/ | J48: Debt/ | K48: Levered | L48: Unlevered
B49: Name | D49: Region | F49: Debt | G49: Equity | H49: Tax Rate 1 | I49: Equity | J49: Capital | K49: Beta 2 | L49: Beta 3
O50: Learner | P50: Correct | Q50: Compare | S50: Learner | T50: Correct | U50: Compare | W50: Learner | X50: Correct | Y50: Compare
B51: Surge Batteries Inc. | D51: Europe | F51: 63702 | G51: 375499.31 | H51: 0.315 | I51: =F51/G51 -> 0.16964612 | J51: =F51/(F51+G51) -> 0.14504055 | K51: 0.85 | L51: =K51/(1+(1-H51)*Inputs!I54) -> 0.84485582 | O51: =SUM(Inputs!I54:I63) -> 0.088888009 | P51: =SUM(I51:I55) -> 0.80833165 | Q51: =IF(O51=0,0,IF(O51=P51,1,0)) -> 0 | S51: =SUM(Inputs!J54:J63) -> 0.088104862 | T51: =SUM(J51:J55) -> 0.6943955 | U51: =IF(S51=0,0,IF(S51=T51,1,0)) -> 0 | W51: =SUM(Inputs!L54:L63) -> 8.6247156 | X51: =SUM(L51:L55) -> 5.0433718 | Y51: =IF(W51=0,0,IF(W51=X51,1,0)) -> 0
B52: Future Energy Co. | D52: Europe | F52: 43422 | G52: 311425.2 | H52: 0.322 | I52: =F52/G52 -> 0.13942995 | J52: =F52/(F52+G52) -> 0.12236816 | K52: 1.01098 | L52: =K52/(1+(1-H52)*Inputs!I60) -> 1.0049237
B53: Clean Green Ltd. | D53: Europe | F53: 26211 | G53: 131995.56 | H53: 0.319 | I53: =F53/G53 -> 0.19857487 | J53: =F53/(F53+G53) -> 0.16567581 | K53: 1.33573 | L53: =K53/(1+(1-H53)*Inputs!I61) -> 1.3276931
B54: Full Power Solutions Ltd. | D54: Europe | F54: 15109 | G54: 95746.138 | H54: 0.33 | I54: =F54/G54 -> 0.15780271 | J54: =F54/(F54+G54) -> 0.13629499 | K54: 0.99399 | L54: =K54/(1+(1-H54)*Inputs!I62) -> 0.98810534
B55: Earthcor Power Inc. | D55: Europe | F55: 95234 | G55: 666540.63 | H55: 0.302 | I55: =F55/G55 -> 0.14287801 | J55: =F55/(F55+G55) -> 0.12501598 | K55: 0.88324 | L55: =K55/(1+(1-H55)*Inputs!I63) -> 0.87779383
G57: Average | H57: =AVERAGE(H51:H55) -> 0.3176 | I57: =AVERAGE(I51:I55) -> 0.16166633 | J57: =AVERAGE(J51:J55) -> 0.1388791 | K57: =AVERAGE(K51:K55) -> 1.014788 | L57: =AVERAGE(L51:L55) -> 1.0086744
G58: Median | H58: =MEDIAN(H51:H55) -> 0.319 | I58: =MEDIAN(I51:I55) -> 0.15780271 | J58: =MEDIAN(J51:J55) -> 0.13629499 | K58: =MEDIAN(K51:K55) -> 0.99399 | L58: =MEDIAN(L51:L55) -> 0.98810534
B61: Risk Premium for Equity | H61: Cost of Equity
B63: Market Risk Premium | F63: 0.047 | H63: Risk Free Rate | L63: 0.024 | O63: Learner | P63: Correct | Q63: Compare | S63: Learner | T63: Correct | U63: Compare
B64: Average Unlevered Beta | F64: =Inputs!L65 -> 0.86247156 | H64: Equity Risk Premium | L64: =Inputs!F74 -> 0.045901244 | O64: =Inputs!F72 -> 0.86247156 | P64: =F64 -> 0.86247156 | Q64: =IF(O64=0,0,IF(O64=P64,1,0)) -> 1 | S64: =Inputs!L72 -> 0.045901244 | T64: =L64 -> 0.045901244 | U64: =IF(S64=0,0,IF(S64=T64,1,0)) -> 1
...

Sheet Model
B3: All figures in USD thousands unless stated | F3: =G3-1 -> 2020 | G3: =H3-1 -> 2021 | H3: =I3-1 -> 2022 | I3: =Inputs!$F$105 -> 2023 | J3: =I3+1 -> 2024 | K3: =J3+1 -> 2025 | L3: =K3+1 -> 2026 | M3: =L3+1 -> 2027 | N3: Term
B4: {=CONCATENATE("Model Running: ",INDEX(Inputs!$B$12:$B$14,Inputs!$D$7)," Drivers")} -> Model Running: Base Case Drivers
B6: Days in Period | C6: =Inputs!$F$108 -> 365 | F6: 365 | G6: 365 | H6: 365 | I6: =$C$6 -> 365 | J6: =$C$6 -> 365 | K6: =$C$6 -> 365 | L6: =$C$6 -> 365 | M6: =$C$6 -> 365 | N6: =$C$6 -> 365
B7: Projected Cost Increase | F7: 0.024 | G7: 0.022 | H7: 0.023 | I7: =Inputs!G17 -> 0.035 | J7: =Inputs!H17 -> 0.03 | K7: =Inputs!I17 -> 0.03 | L7: =Inputs!J17 -> 0.025 | M7: =Inputs!K17 -> 0.025 | N7: =Inputs!L17 -> 0.015
B9: Income Statement
B11: All figures in USD thousands unless stated | F11: =F$3 -> 2020 | G11: =G$3 -> 2021 | H11: =H$3 -> 2022 | I11: =I$3 -> 2023 | J11: =J$3 -> 2024 | K11: =K$3 -> 2025 | L11: =L$3 -> 2026 | M11: =M$3 -> 2027 | N11: =N$3 -> Term
B12: =$B$4 -> Model Running: Base Case Drivers
B14: Inflation Rate | F14: 0.024 | G14: 0.022 | H14: 0.023 | I14: =Inputs!G31 -> 0.035 | J14: =Inputs!H31 -> 0.03 | K14: =Inputs!I31 -> 0.03 | L14: =Inputs!J31 -> 0.025 | M14: =Inputs!K31 -> 0.025 | N14: =Inputs!L31 -> 0.015
B17: Tax Rate | C17: =Inputs!$L$81 -> 0.25
B19: Revenue | F19: 50589 | G19: 51647.865 | H19: 53760.85 | I19: =H19*(1+Inputs!G10) -> 55373.675 | J19: =I19*(1+Inputs!H10) -> 56481.149 | K19: =J19*(1+Inputs!I10) -> 57610.772 | L19: =K19*(1+Inputs!J10) -> 58474.934 | M19: =L19*(1+Inputs!K10) -> 59352.058 | N19: =M19*(1+Inputs!L10) -> 59945.578 | P19: ok
B20: COGS | F20: -24544.3 | G20: -25104.014 | H20: -25779.401 | I20: =H20*(1+I7) -> -26681.681 | J20: =I20*(1+J7) -> -27482.131 | K20: =J20*(1+K7) -> -28306.595 | L20: =K20*(1+L7) -> -29014.26 | M20: =L20*(1+M7) -> -29739.616 | N20: =M20*(1+N7) -> -30185.711 | P20: ok
B21: Gross Profit | F21: =F19+F20 -> 26044.7 | G21: =G19+G20 -> 26543.851 | H21: =H19+H20 -> 27981.448 | I21: =I19+I20 -> 28691.995 | J21: =J19+J20 -> 28999.018 | K21: =K19+K20 -> 29304.177 | L21: =L19+L20 -> 29460.674 | M21: =M19+M20 -> 29612.441 | N21: =N19+N20 -> 29759.868 | P21: ok
B24: SG&A | F24: -5877 | G24: -6006 | H24: -6144 | I24: =H24*(1+I14) -> -6359.04 | J24: =I24*(1+J14) -> -6549.8112 | K24: =J24*(1+K14) -> -6746.3055 | L24: =K24*(1+L14) -> -6914.9632 | M24: =L24*(1+M14) -> -7087.8373 | N24: =M24*(1+N14) -> -7194.1548 | P24: ok
B25: Other | F25: -1764 | G25: -1931 | H25: -2026 | I25: =H25*(1+I14) -> -2096.91 | J25: =I25*(1+J14) -> -2159.8173 | K25: =J25*(1+K14) -> -2224.6118 | L25: =K25*(1+L14) -> -2280.2271 | M25: =L25*(1+M14) -> -2337.2328 | N25: =M25*(1+N14) -> -2372.2913 | P25: ok
B26: EBITDA | F26: =F21+SUM(F24:F25) -> 18403.7 | G26: =G21+SUM(G24:G25) -> 18606.851 | H26: =H21+SUM(H24:H25) -> 19811.448 | I26: =I21+SUM(I24:I25) -> 20236.045 | J26: =J21+SUM(J24:J25) -> 20289.39 | K26: =K21+SUM(K24:K25) -> 20333.26 | L26: =L21+SUM(L24:L25) -> 20265.484 | M26: =M21+SUM(M24:M25) -> 20187.371 | N26: =N21+SUM(N24:N25) -> 20193.422 | P26: ok
B28: Amortization
B29: Depreciation | F29: -2960 | G29: -3196 | H29: -3452 | I29: =I197*-1 -> -4962.9375 | J29: =J197*-1 -> -5412.9375 | K29: =K197*-1 -> -5837.9375 | L29: =L197*-1 -> -6187.9375 | M29: =M197*-1 -> -6437.9375 | N29: =N197*-1 -> -6712.9375
B30: EBIT | F30: =F26+F29 -> 15443.7 | G30: =G26+G29 -> 15410.851 | H30: =H26+H29 -> 16359.448 | I30: =I26+I29 -> 15273.107 | J30: =J26+J29 -> 14876.452 | K30: =K26+K29 -> 14495.322 | L30: =L26+L29 -> 14077.546 | M30: =M26+M29 -> 13749.434 | N30: =N26+N29 -> 13480.484
B32: Interest Expense | F32: -1688 | G32: -2200 | H32: -2350 | I32: =I295*-1 -> -1110 | J32: =J295*-1 -> -930 | K32: =K295*-1 -> -780 | L32: =L295*-1 -> -630 | M32: =M295*-1 -> -450 | N32: =N295*-1 -> -300
B33: Interest Income | F33: 200 | G33: 180 | H33: 193 | I33: =I296*-1 -> 84.099991 | J33: =J296*-1 -> 110.66679 | K33: =K296*-1 -> 160.91113 | L33: =L296*-1 -> 184.93386 | M33: =M296*-1 -> 240.31815 | N33: =N296*-1 -> 296.1942
B34: EBT | F34: =F30+F32+F33 -> 13955.7 | G34: =G30+G32+G33 -> 13390.851 | H34: =H30+H32+H33 -> 14202.448 | I34: =I30+I32+I33 -> 14247.207 | J34: =J30+J32+J33 -> 14057.119 | K34: =K30+K32+K33 -> 13876.233 | L34: =L30+L32+L33 -> 13632.48 | M34: =M30+M32+M33 -> 13539.752 | N34: =N30+N32+N33 -> 13476.678
B36: Current Tax | F36: 0 | G36: 0 | H36: 0 | I36: =I363 -> 0 | J36: =J363 -> 233.41219 | K36: =K363 -> 3125.0759 | L36: =L363 -> 3159.6576 | M36: =M363 -> 3280.7926 | N36: =N34*C17 -> 3369.1696
B37: Deferred Tax | F37: 3155 | G37: 2861 | H37: 3012 | I37: =I364 -> 3561.8019 | J37: =J364 -> 3280.8675 | K37: =K364 -> 343.98241 | L37: =L364 -> 248.46239 | M37: =M364 -> 104.14537 | N37: =N364 -> 0
B38: Total Tax | F38: =SUM(F36:F37) -> 3155 | G38: =SUM(G36:G37) -> 2861 | H38: =SUM(H36:H37) -> 3012 | I38: =SUM(I36:I37) -> 3561.8019 | J38: =SUM(J36:J37) -> 3514.2797 | K38: =SUM(K36:K37) -> 3469.0583 | L38: =SUM(L36:L37) -> 3408.12 | M38: =SUM(M36:M37) -> 3384.938 | N38: =SUM(N36:N37) -> 3369.1696
B40: Net Income | F40: =F34-F38 -> 10800.7 | G40: =G34-G38 -> 10529.851 | H40: =H34-H38 -> 11190.448 | I40: =I34-I38 -> 10685.406 | J40: =J34-J38 -> 10542.839 | K40: =K34-K38 -> 10407.175 | L40: =L34-L38 -> 10224.36 | M40: =M34-M38 -> 10154.814 | N40: =N34-N38 -> 10107.509
B44: Cash Flow Statement
B46: All figures in USD thousands unless stated | F46: =F$3 -> 2020 | G46: =G$3 -> 2021 | H46: =H$3 -> 2022 | I46: =I$3 -> 2023 | J46: =J$3 -> 2024 | K46: =K$3 -> 2025 | L46: =L$3 -> 2026 | M46: =M$3 -> 2027 | N46: =N$3 -> Term
B50: CASH FROM OPERATING
B51: Net Income | F51: =F40 -> 10800.7 | G51: =G40 -> 10529.851 | H51: =H40 -> 11190.448 | I51: =I40 -> 10685.406 | J51: =J40 -> 10542.839 | K51: =K40 -> 10407.175 | L51: =L40 -> 10224.36 | M51: =M40 -> 10154.814 | N51: =N40 -> 10107.509 | P51: ok
B52: Deferred Taxes | F52: =F37 -> 3155 | G52: =G37 -> 2861 | H52: =H37 -> 3012 | I52: =I37 -> 3561.8019 | J52: =J37 -> 3280.8675 | K52: =K37 -> 343.98241 | L52: =L37 -> 248.46239 | M52: =M37 -> 104.14537 | ... O52: =O37 -> 0 | P52: ok
B53: Depreciation | F53: =F29*-1 -> 2960 | G53: =G29*-1 -> 3196 | H53: =H29*-1 -> 3452 | I53: =I29*-1 -> 4962.9375 | J53: =J29*-1 -> 5412.9375 | K53: =K29*-1 -> 5837.9375 | L53: =L29*-1 -> 6187.9375 | M53: =M29*-1 -> 6437.9375 | N53: =N29*-1 -> 6712.9375 | P53: ok
B54: Cash From Accounts Receivable | F54: -600 | G54: =F140-G140 -> -625 | H54: =G140-H140 -> -291 | I54: =H140-I140 -> -202.8915 | J54: =I140-J140 -> -136.53783 | K54: =J140-K140 -> -139.26859 | L54: =K140-L140 -> -106.54047 | M54: =L140-M140 -> -108.13858 | N54: =M140-N140 -> -73.17377
B55: Cash From Inventory | F55: -400 | G55: =F141-G141 -> -131 | H55: =G141-H141 -> -86 | I55: =H141-I141 -> 181.48763 | J55: =I141-J141 -> -54.825371 | K55: =J141-K141 -> -56.470132 | L55: =K141-L141 -> -48.470197 | M55: =L141-M141 -> -49.681952 | N55: =M141-N141 -> -30.5544
B56: Cash From Accounts Payable | F56: -260 | G56: =G142-F142 -> 181 | H56: =H142-G142 -> 114 | I56: =I142-H142 -> -394.98021 | J56: =J142-I142 -> 87.720594 | K56: =K142-J142 -> 90.352211 | L56: =L142-K142 -> 77.552315 | M56: =M142-L142 -> 79.491123 | N56: =N142-M142 -> 48.88704
B57: Subtotal | F57: =SUM(F51:F56) -> 15655.7 | G57: =SUM(G51:G56) -> 16011.851 | H57: =SUM(H51:H56) -> 17391.448 | I57: =SUM(I51:I56) -> 18793.761 | J57: =SUM(J51:J56) -> 19133.002 | K57: =SUM(K51:K56) -> 16483.708 | L57: =SUM(L51:L56) -> 16583.301 | M57: =SUM(M51:M56) -> 16618.567 | N57: =SUM(N51:N56) -> 16765.605
B60: CASH FROM INVESTING
B61: Capital Expenditure | F61: =F163*-1 -> -9015 | G61: =G163*-1 -> -11733 | H61: =H163*-1 -> -11130 | I61: =I163*-1 -> -10000 | J61: =J163*-1 -> -8000 | K61: =K163*-1 -> -9000 | L61: =L163*-1 -> -5000 | M61: =M163*-1 -> -5000 | N61: =N163*-1 -> -6000 | P61: ok
B62: Subtotal | F62: =SUM(F61) -> -9015 | G62: =SUM(G61) -> -11733 | H62: =SUM(H61) -> -11130 | I62: =SUM(I61) -> -10000 | J62: =SUM(J61) -> -8000 | K62: =SUM(K61) -> -9000 | L62: =SUM(L61) -> -5000 | M62: =SUM(M61) -> -5000 | N62: =SUM(N61) -> -6000
B65: CASH FROM FINANCING
B66: Change in Long-Term Debt | F66: 0 | G66: -4000 | H66: -4000 | I66: =Inputs!G41 -> -3000 | J66: =Inputs!H41 -> -3000 | K66: =Inputs!I41 -> -2000 | L66: =Inputs!J41 -> -3000 | M66: =Inputs!K41 -> -3000 | N66: =Inputs!L41 -> -2000
...

Sheet Outputs
B3: Dashboard: Perpetuity Method
D6: Model Drivers Set To | F6: 2 | L6: All figures in USD thousands unless stated
D9: Main Outputs 1 | L9: Selected Inputs
F11: Enterprise | G11: Equity | H11: Equity
F12: Value | G12: Value | H12: Per Share | L12: Terminal Growth Rate | O12: =Inputs!$F$115 -> 0.01
E13: ='Outputs-R'!Y11 -> 1 | F13: =Model!H488 -> 125713.01 | L13: WACC | O13: =Inputs!$L$92 -> 0.095866057
D14: Best Case | E14: 1 | F14: 176515.71 | G14: =F14-$O$14 -> 157873.71 | H14: =G14/$O$15 -> 4.6161905 | L14: Net Debt | N14: =CONCATENATE("(End of ",Model!$H$3,")") -> (End of 2022) | O14: =Inputs!$L$102 -> 18642
D15: Base Case | E15: 2 | F15: 125713.01 | G15: =F15-$O$14 -> 107071.01 | H15: =G15/$O$15 -> 3.1307312 | L15: Shares Outstanding | N15: (FD 000) | O15: =Inputs!$F$113 -> 34200
D16: Worst Case | E16: 3 | F16: 86963.94 | G16: =F16-$O$14 -> 68321.94 | H16: =G16/$O$15 -> 1.9977176 | L16: Current Stock Price | N16: (US$/sh) | O16: =Inputs!$F$114 -> 2.23
E17: ='Outputs-R'!U18 -> 1 | F17: ='Outputs-R'!Y18 -> 0 | G17: ='Outputs-R'!AC18 -> 1 | H17: ='Outputs-R'!AG18 -> 1
D20: Enterprise Value 1 | L20: Equity Value per Share
D22: Terminal Growth Rate | L22: Terminal Growth Rate
B23: ='Outputs-R'!U21 -> 1 | C23: =Model!H488 -> 125713.01 | D23: =E23-0.005 -> 0 | E23: =F23-0.005 -> 0.005 | F23: =Inputs!$F$115 -> 0.01 | G23: =F23+0.005 -> 0.015 | H23: =G23+0.005 -> 0.02 | L23: =D23 -> 0 | M23: =E23 -> 0.005 | N23: =F23 -> 0.01 | O23: =G23 -> 0.015 | P23: =H23 -> 0.02
B24: WACC | C24: =C25-0.01 -> 0.075866057 | D24: 125713.01 | E24: 125713.01 | F24: 125713.01 | G24: 125713.01 | H24: 125713.01 | J24: WACC | K24: =C24 -> 0.075866057 | L24: =D37/$O$15 -> 3.1307312 | M24: =E37/$O$15 -> 3.1307312 | N24: =F37/$O$15 -> 3.1307312 | O24: =G37/$O$15 -> 3.1307312 | P24: =H37/$O$15 -> 3.1307312
C25: =C26-0.01 -> 0.085866057 | D25: 125713.01 | E25: 125713.01 | F25: 125713.01 | G25: 125713.01 | H25: 125713.01 | K25: =C25 -> 0.085866057 | L25: =D38/$O$15 -> 3.1307312 | M25: =E38/$O$15 -> 3.1307312 | N25: =F38/$O$15 -> 3.1307312 | O25: =G38/$O$15 -> 3.1307312 | P25: =H38/$O$15 -> 3.1307312
C26: =Inputs!$L$92 -> 0.095866057 | D26: 125713.01 | E26: 125713.01 | F26: 125713.01 | G26: 125713.01 | H26: 125713.01 | K26: =C26 -> 0.095866057 | L26: =D39/$O$15 -> 3.1307312 | M26: =E39/$O$15 -> 3.1307312 | N26: =F39/$O$15 -> 3.1307312 | O26: =G39/$O$15 -> 3.1307312 | P26: =H39/$O$15 -> 3.1307312
C27: =C26+0.01 -> 0.10586606 | D27: 125713.01 | E27: 125713.01 | F27: 125713.01 | G27: 125713.01 | H27: 125713.01 | K27: =C27 -> 0.10586606 | L27: =D40/$O$15 -> 3.1307312 | M27: =E40/$O$15 -> 3.1307312 | N27: =F40/$O$15 -> 3.1307312 | O27: =G40/$O$15 -> 3.1307312 | P27: =H40/$O$15 -> 3.1307312
C28: =C27+0.01 -> 0.11586606 | D28: 125713.01 | E28: 125713.01 | F28: 125713.01 | G28: 125713.01 | H28: 125713.01 | K28: =C28 -> 0.11586606 | L28: =D41/$O$15 -> 3.1307312 | M28: =E41/$O$15 -> 3.1307312 | N28: =F41/$O$15 -> 3.1307312 | O28: =G41/$O$15 -> 3.1307312 | P28: =H41/$O$15 -> 3.1307312
H29: ='Outputs-R'!AE30 -> 1 | P29: ='Outputs-R'!Y37 -> 1
D33: Equity Value | L33: Premium (Discount) to Stock Price
D35: Terminal Growth Rate | L35: Terminal Growth Rate
D36: =D23 -> 0 | E36: =E23 -> 0.005 | F36: =F23 -> 0.01 | G36: =G23 -> 0.015 | H36: =H23 -> 0.02 | L36: =D36 -> 0 | M36: =E36 -> 0.005 | N36: =F36 -> 0.01 | O36: =G36 -> 0.015 | P36: =H36 -> 0.02
B37: WACC | C37: =C24 -> 0.075866057 | D37: =D24-$O$14 -> 107071.01 | E37: =E24-$O$14 -> 107071.01 | F37: =F24-$O$14 -> 107071.01 | G37: =G24-$O$14 -> 107071.01 | H37: =H24-$O$14 -> 107071.01 | J37: WACC | K37: =C37 -> 0.075866057 | L37: =L24/$O$16-1 -> 0.40391535 | M37: =M24/$O$16-1 -> 0.40391535 | N37: =N24/$O$16-1 -> 0.40391535 | O37: =O24/$O$16-1 -> 0.40391535 | P37: =P24/$O$16-1 -> 0.40391535
C38: =C25 -> 0.085866057 | D38: =D25-$O$14 -> 107071.01 | E38: =E25-$O$14 -> 107071.01 | F38: =F25-$O$14 -> 107071.01 | G38: =G25-$O$14 -> 107071.01 | H38: =H25-$O$14 -> 107071.01 | K38: =C38 -> 0.085866057 | L38: =L25/$O$16-1 -> 0.40391535 | M38: =M25/$O$16-1 -> 0.40391535 | N38: =N25/$O$16-1 -> 0.40391535 | O38: =O25/$O$16-1 -> 0.40391535 | P38: =P25/$O$16-1 -> 0.40391535
C39: =C26 -> 0.095866057 | D39: =D26-$O$14 -> 107071.01 | E39: =E26-$O$14 -> 107071.01 | F39: =F26-$O$14 -> 107071.01 | G39: =G26-$O$14 -> 107071.01 | H39: =H26-$O$14 -> 107071.01 | K39: =C39 -> 0.095866057 | L39: =L26/$O$16-1 -> 0.40391535 | M39: =M26/$O$16-1 -> 0.40391535 | N39: =N26/$O$16-1 -> 0.40391535 | O39: =O26/$O$16-1 -> 0.40391535 | P39: =P26/$O$16-1 -> 0.40391535
C40: =C27 -> 0.10586606 | D40: =D27-$O$14 -> 107071.01 | E40: =E27-$O$14 -> 107071.01 | F40: =F27-$O$14 -> 107071.01 | G40: =G27-$O$14 -> 107071.01 | H40: =H27-$O$14 -> 107071.01 | K40: =C40 -> 0.10586606 | L40: =L27/$O$16-1 -> 0.40391535 | M40: =M27/$O$16-1 -> 0.40391535 | N40: =N27/$O$16-1 -> 0.40391535 | O40: =O27/$O$16-1 -> 0.40391535 | P40: =P27/$O$16-1 -> 0.40391535
C41: =C28 -> 0.11586606 | D41: =D28-$O$14 -> 107071.01 | E41: =E28-$O$14 -> 107071.01 | F41: =F28-$O$14 -> 107071.01 | G41: =G28-$O$14 -> 107071.01 | H41: =H28-$O$14 -> 107071.01 | K41: =C41 -> 0.11586606 | L41: =L28/$O$16-1 -> 0.40391535 | M41: =M28/$O$16-1 -> 0.40391535 | N41: =N28/$O$16-1 -> 0.40391535 | O41: =O28/$O$16-1 -> 0.40391535 | P41: =P28/$O$16-1 -> 0.40391535
H42: ='Outputs-R'!U40 -> 1 | P42: ='Outputs-R'!Y40 -> 1
D43: ='Outputs-R'!S43 | P43: These tables require the workbook calculation to be set to automatic to update.
B47: Dashboard: Multiple Method
D50: Model Drivers Set To | F50: =F6 -> 2 | L50: All figures in USD thousands unless stated
D53: Main Outputs 1 | L53: Selected Inputs
F55: Enterprise | G55: Equity | H55: Equity
F56: Value | G56: Value | H56: Per Share | L56: Terminal Multiple | O56: =+Inputs!$F$116 -> 7
E57: ='Outputs-R'!Y55 -> 1 | F57: =Model!H535 -> 130862.76 | L57: WACC | O57: =Inputs!$L$92 -> 0.095866057
D58: =D14 -> Best Case | E58: 1 | F58: 163673.86 | G58: =F58-$O$58 -> 145031.86 | H58: =+G58/$O$59 -> 4.2406978 | L58: Net Debt | N58: =N14 -> (End of 2022) | O58: =Inputs!$L$102 -> 18642
D59: =D15 -> Base Case | E59: 2 | F59: 130862.76 | G59: =F59-$O$58 -> 112220.76 | H59: =+G59/$O$59 -> 3.2813089 | L59: Shares Outstanding | N59: (FD 000) | O59: =Inputs!$F$113 -> 34200
D60: =D16 -> Worst Case | E60: 3 | F60: 101841.48 | G60: =F60-$O$58 -> 83199.483 | H60: =+G60/$O$59 -> 2.4327334 | L60: Current Stock Price | N60: (US$/sh) | O60: =Inputs!$F$114 -> 2.23
E61: ='Outputs-R'!U58 -> 1 | F61: ='Outputs-R'!Y62 -> 0
D64: Enterprise Value 1 | L64: Equity Value per Share
...

Sheet Relative Valuation
B3: Relative Valuation - Using Comparable Company Analysis
B5: All figures in USD thousands unless stated
E8: Share | F8: Shares | G8: Market | H8: Net | I8: Enterprise | J8: EBITDA | L8: Net Income | N8: EV / EBITDA | P8: P / E 2
B9: Peer Companies | C9: Industry | D9: Location | E9: Price | F9: Outstand. | G9: Cap | H9: Debt | I9: Value 1 | J9: 2022 | K9: 2023 | L9: 2022 | M9: 2023 | N9: 2022 | O9: 2023 | P9: 2022 | Q9: 2023
E10: $ | F10: mm | N10: x | O10: x | P10: x | Q10: x
B11: =Inputs!B54 -> Peer 1 | C11: =Inputs!C54 -> Industry 1 | D11: =Inputs!D54 -> Canada | E11: 3.88 | F11: 25000 | G11: =E11*F11 -> 97000 | H11: 25000 | I11: =G11+H11 -> 122000 | J11: 22222 | K11: 33333 | L11: 11111 | M11: 12345 | N11: =IFERROR($I11/J11,"NA") -> 5.4900549 | O11: =IFERROR($I11/K11,"NA") -> 3.6600366 | P11: =IFERROR($G11/L11,"NA") -> 8.7300873 | Q11: =IFERROR($G11/M11,"NA") -> 7.8574322
B12: =Inputs!B55 -> Peer 2 | C12: =Inputs!C55 -> Industry 2 | D12: =Inputs!D55 -> USA | E12: 3.88 | F12: 25000 | G12: =E12*F12 -> 97000 | H12: 25000 | I12: =G12+H12 -> 122000 | J12: 22222 | K12: 33333 | L12: 11111 | M12: 12345 | N12: =IFERROR($I12/J12,"NA") -> 5.4900549 | O12: =IFERROR($I12/K12,"NA") -> 3.6600366 | P12: =IFERROR($G12/L12,"NA") -> 8.7300873 | Q12: =IFERROR($G12/M12,"NA") -> 7.8574322
B13: =Inputs!B56 -> Peer 3 | C13: =Inputs!C56 -> Industry 3 | D13: =Inputs!D56 -> USA | E13: 3.88 | F13: 25000 | G13: =E13*F13 -> 97000 | H13: 25000 | I13: =G13+H13 -> 122000 | J13: 22222 | K13: 33333 | L13: 11111 | M13: 12345 | N13: =IFERROR($I13/J13,"NA") -> 5.4900549 | O13: =IFERROR($I13/K13,"NA") -> 3.6600366 | P13: =IFERROR($G13/L13,"NA") -> 8.7300873 | Q13: =IFERROR($G13/M13,"NA") -> 7.8574322
B14: =Inputs!B57 -> Peer 4 | C14: =Inputs!C57 -> Industry 4 | D14: =Inputs!D57 -> USA | E14: 3.88 | F14: 25000 | G14: =E14*F14 -> 97000 | H14: 25000 | I14: =G14+H14 -> 122000 | J14: 22222 | K14: 33333 | L14: 11111 | M14: 12345 | N14: =IFERROR($I14/J14,"NA") -> 5.4900549 | O14: =IFERROR($I14/K14,"NA") -> 3.6600366 | P14: =IFERROR($G14/L14,"NA") -> 8.7300873 | Q14: =IFERROR($G14/M14,"NA") -> 7.8574322
B15: =Inputs!B58 -> Peer 5 | C15: =Inputs!C58 -> Industry 5 | D15: =Inputs!D58 -> Canada | E15: 3.88 | F15: 25000 | G15: =E15*F15 -> 97000 | H15: 25000 | I15: =G15+H15 -> 122000 | J15: 22222 | K15: 33333 | L15: 11111 | M15: 12345 | N15: =IFERROR($I15/J15,"NA") -> 5.4900549 | O15: =IFERROR($I15/K15,"NA") -> 3.6600366 | P15: =IFERROR($G15/L15,"NA") -> 8.7300873 | Q15: =IFERROR($G15/M15,"NA") -> 7.8574322
B16: =Inputs!B59 -> Peer 6 | C16: =Inputs!C59 -> Industry 6 | D16: =Inputs!D59 -> Canada | E16: 3.88 | F16: 25000 | G16: =E16*F16 -> 97000 | H16: 25000 | I16: =G16+H16 -> 122000 | J16: 22222 | K16: 33333 | L16: 11111 | M16: 12345 | N16: =IFERROR($I16/J16,"NA") -> 5.4900549 | O16: =IFERROR($I16/K16,"NA") -> 3.6600366 | P16: =IFERROR($G16/L16,"NA") -> 8.7300873 | Q16: =IFERROR($G16/M16,"NA") -> 7.8574322
B17: =Inputs!B60 -> Peer 7 | C17: =Inputs!C60 -> Industry 7 | D17: =Inputs!D60 -> USA | E17: 3.88 | F17: 25000 | G17: =E17*F17 -> 97000 | H17: 25000 | I17: =G17+H17 -> 122000 | J17: 22222 | K17: 33333 | L17: 11111 | M17: 12345 | N17: =IFERROR($I17/J17,"NA") -> 5.4900549 | O17: =IFERROR($I17/K17,"NA") -> 3.6600366 | P17: =IFERROR($G17/L17,"NA") -> 8.7300873 | Q17: =IFERROR($G17/M17,"NA") -> 7.8574322
B18: =Inputs!B61 -> Peer 8 | C18: =Inputs!C61 -> Industry 8 | D18: =Inputs!D61 -> Canada | E18: 3.88 | F18: 25000 | G18: =E18*F18 -> 97000 | H18: 25000 | I18: =G18+H18 -> 122000 | J18: 22222 | K18: 33333 | L18: 11111 | M18: 12345 | N18: =IFERROR($I18/J18,"NA") -> 5.4900549 | O18: =IFERROR($I18/K18,"NA") -> 3.6600366 | P18: =IFERROR($G18/L18,"NA") -> 8.7300873 | Q18: =IFERROR($G18/M18,"NA") -> 7.8574322
B19: =Inputs!B62 -> Peer 9 | C19: =Inputs!C62 -> Industry 9 | D19: =Inputs!D62 -> Ghana | E19: 3.88 | F19: 25000 | G19: =E19*F19 -> 97000 | H19: 25000 | I19: =G19+H19 -> 122000 | J19: 22222 | K19: 33333 | L19: 11111 | M19: 12345 | N19: =IFERROR($I19/J19,"NA") -> 5.4900549 | O19: =IFERROR($I19/K19,"NA") -> 3.6600366 | P19: =IFERROR($G19/L19,"NA") -> 8.7300873 | Q19: =IFERROR($G19/M19,"NA") -> 7.8574322
B20: =Inputs!B63 -> Peer 10 | C20: =Inputs!C63 -> Industry 10 | D20: =Inputs!D63 -> China | E20: 3.88 | F20: 25000 | G20: =E20*F20 -> 97000 | H20: 25000 | I20: =G20+H20 -> 122000 | J20: 22222 | K20: 33333 | L20: 11111 | M20: 12345 | N20: =IFERROR($I20/J20,"NA") -> 5.4900549 | O20: =IFERROR($I20/K20,"NA") -> 3.6600366 | P20: =IFERROR($G20/L20,"NA") -> 8.7300873 | Q20: =IFERROR($G20/M20,"NA") -> 7.8574322
B23: Average | N23: =+AVERAGE(N$11:N$16) -> 5.4900549 | O23: =+AVERAGE(O$11:O$16) -> 3.6600366 | P23: =+AVERAGE(P$11:P$16) -> 8.7300873 | Q23: =+AVERAGE(Q$11:Q$16) -> 7.8574322
B24: Median | N24: =+MEDIAN(N$11:N$16) -> 5.4900549 | O24: =+MEDIAN(O$11:O$16) -> 3.6600366 | P24: =+MEDIAN(P$11:P$16) -> 8.7300873 | Q24: =+MEDIAN(Q$11:Q$16) -> 7.8574322
B25: Maximum | N25: =+MAX(N$11:N$16) -> 5.4900549 | O25: =+MAX(O$11:O$16) -> 3.6600366 | P25: =+MAX(P$11:P$16) -> 8.7300873 | Q25: =+MAX(Q$11:Q$16) -> 7.8574322
B26: Minimum | N26: =+MIN(N$11:N$16) -> 5.4900549 | O26: =+MIN(O$11:O$16) -> 3.6600366 | P26: =+MIN(P$11:P$16) -> 8.7300873 | Q26: =+MIN(Q$11:Q$16) -> 7.8574322
B29: Target Company Value at Median Multiples
B30: =$J$9&"A EV/EBITDA" -> 2022A EV/EBITDA | E30: =G30/F30 -> 2.6352029 | F30: =Inputs!F113 -> 34200 | G30: =I30-H30 -> 90123.94 | H30: =Inputs!L102 -> 18642 | I30: =J30*N30 -> 108765.94 | J30: =Model!H562 -> 19811.448 | N30: =N24 -> 5.4900549
B31: =$K$9&"F EV/EBITDA" -> 2023F EV/EBITDA | E31: =G31/F31 -> 1.6205458 | F31: =F30 -> 34200 | G31: =I31-H31 -> 55422.665 | H31: =H30 -> 18642 | I31: =K31*O31 -> 74064.665 | K31: =Model!I562 -> 20236.045 | O31: =O24 -> 3.6600366
B32: =$L$9&"A P/E" -> 2022A P/E | E32: =G32/F32 -> 2.8565378 | F32: =F31 -> 34200 | G32: =L32*P32 -> 97693.592 | H32: =H31 -> 18642 | I32: =G32+H32 -> 116335.59 | L32: =Model!H554 -> 11190.448 | P32: =P24 -> 8.7300873
B33: =$M$9&"F P/E" -> 2023F P/E | E33: =G33/F33 -> 2.4549664 | F33: =F32 -> 34200 | G33: =+M33*Q33 -> 83959.849 | H33: =H32 -> 18642 | I33: =G33+H33 -> 102601.85 | M33: =Model!I554 -> 10685.406 | Q33: =Q24 -> 7.8574322
Q36: Enterprise Value = Market Cap + Net Debt.
Q37: Calculated as Market Cap divided by Net Income.
B42: Relative Valuation - Using Precedent Transaction Analysis
B44: All figures in USD thousands unless stated
E46: Share | F46: Offer | G46: Control | H46: Shares | I46: Market Cap | J46: Net | K46: Enterprise | L46: EBITDA | O46: EV / EBITDA
B47: Date | C47: Acquirer | D47: Target | E47: Price | F47: Price | G47: Premium | H47: Outstand. | I47: at Offer | J47: Debt | K47: Value | L47: 2022 | M47: 2023 | N47: 2024 | O47: 2022 | P47: 2023 | Q47: 2024
B48: (YYYY-MM-DD) | E48: $ | F48: $ | H48: mm | O48: x | P48: x | Q48: x
B49: 44631 | C49: Cake | D49: Ice Cream | E49: 25.5 | F49: 31.11 | G49: =F49/E49-1 -> 0.22 | H49: 129 | I49: =H49*F49 -> 4013.19 | J49: 2528.3097 | K49: =I49+J49 -> 6541.4997 | L49: 485 | M49: 509.25 | N49: 534.7125 | O49: =IFERROR($K49/L49,"NA") -> 13.487628 | P49: =IFERROR($K49/M49,"NA") -> 12.84536 | Q49: =IFERROR($K49/N49,"NA") -> 12.233676
B50: 44626 | C50: Salt | D50: Pepper | E50: 37.25 | F50: 46.56 | G50: =F50/E50-1 -> 0.24993289 | H50: 568 | I50: =H50*F50 -> 26446.08 | J50: 18247.795 | K50: =I50+J50 -> 44693.875 | L50: 4382 | M50: 4688.74 | N50: 5063.8392 | O50: =IFERROR($K50/L50,"NA") -> 10.199424 | P50: =IFERROR($K50/M50,"NA") -> 9.5321718 | Q50: =IFERROR($K50/N50,"NA") -> 8.826085
B51: 44456 | C51: Fish | D51: Chips | E51: 16.8 | F51: 21.17 | G51: =F51/E51-1 -> 0.26011905 | H51: 688 | I51: =H51*F51 -> 14564.96 | J51: 9758.5232 | K51: =I51+J51 -> 24323.483 | L51: 1622 | M51: 1784.2 | N51: 1891.252 | O51: =IFERROR($K51/L51,"NA") -> 14.995982 | P51: =IFERROR($K51/M51,"NA") -> 13.632711 | Q51: =IFERROR($K51/N51,"NA") -> 12.861048
B52: 44148 | C52: Peanut Butter | D52: Jelly | E52: 31.11 | F52: 37.33 | G52: =F52/E52-1 -> 0.19993571 | H52: 1429 | I52: =H52*F52 -> 53344.57 | J52: 34673.97 | K52: =I52+J52 -> 88018.541 | L52: 8075 | M52: 8882.5 | N52: 9681.925 | O52: =IFERROR($K52/L52,"NA") -> 10.900129 | P52: =IFERROR($K52/M52,"NA") -> 9.909208 | Q52: =IFERROR($K52/N52,"NA") -> 9.0910166
B53: 44056 | C53: Brisket | D53: NoSauce | E53: 29.29 | F53: 37.2 | G53: =F53/E53-1 -> 0.27005804 | H53: 1198 | I53: =H53*F53 -> 44565.6 | J53: 27630.672 | K53: =I53+J53 -> 72196.272 | L53: 4512 | M53: 4918.08 | N53: 5311.5264 | O53: =IFERROR($K53/L53,"NA") -> 16.000947 | P53: =IFERROR($K53/M53,"NA") -> 14.679768 | Q53: =IFERROR($K53/N53,"NA") -> 13.592378
B54: 43952 | C54: Biscuits | D54: Gravy | E54: 12.34 | F54: 15.3 | G54: =F54/E54-1 -> 0.23987034 | H54: 934 | I54: =H54*F54 -> 14290.2 | J54: 9145.728 | K54: =I54+J54 -> 23435.928 | L54: 2092 | M54: 2280.28 | N54: 2485.5052 | O54: =IFERROR($K54/L54,"NA") -> 11.202642 | P54: =IFERROR($K54/M54,"NA") -> 10.277654 | Q54: =IFERROR($K54/N54,"NA") -> 9.42904
B55: 44091 | C55: CTM | D55: GTM | E55: 9 | F55: 8.75 | G55: =F55/E55-1 -> -0.027777778 | H55: 156 | I55: =H55*F55 -> 1365 | J55: 859.95 | K55: =I55+J55 -> 2224.95 | L55: 371 | M55: 404.39 | N55: 424.6095 | O55: =IFERROR($K55/L55,"NA") -> 5.9971698 | P55: =IFERROR($K55/M55,"NA") -> 5.5019907 | Q55: =IFERROR($K55/N55,"NA") -> 5.2399911
B56: 42264 | C56: CTM | D56: Jik | E56: 23.82 | F56: 30.4896 | G56: =F56/E56-1 -> 0.28 | H56: 1219 | I56: =H56*F56 -> 37166.822 | J56: 25273.439 | K56: =I56+J56 -> 62440.262 | L56: 4995 | M56: 5144.85 | N56: 5299.1955 | O56: =IFERROR($K56/L56,"NA") -> 12.500553 | P56: =IFERROR($K56/M56,"NA") -> 12.136459 | Q56: =IFERROR($K56/N56,"NA") -> 11.78297
B57: 41956 | C57: Octane | D57: Lime | E57: 60 | F57: 72.5 | G57: =F57/E57-1 -> 0.20833333 | H57: 141 | I57: =H57*F57 -> 10222.5 | J57: 6337.95 | K57: =I57+J57 -> 16560.45 | L57: 974 | M57: 1071.4 | N57: 1178.54 | O57: =IFERROR($K57/L57,"NA") -> 17.002515 | P57: =IFERROR($K57/M57,"NA") -> 15.456832 | Q57: =IFERROR($K57/N57,"NA") -> 14.051666
...

Sheet Football Field Chart
B3: Football Field Chart
E36: Low | F36: Middle | G36: High
D37: Comparable Companies | E37: =MIN('Relative Valuation'!E30:E33) -> 1.6205458 | F37: =G37-E37 -> 1.235992 | G37: =MAX('Relative Valuation'!E30:E33) -> 2.8565378
D38: Precedent Transactions | E38: =MIN('Relative Valuation'!F68:F70) -> 5.8806914 | F38: =G38-E38 -> 0.72553705 | G38: =MAX('Relative Valuation'!F68:F70) -> 6.6062285
D39: DCF - Perpetuity Growth | E39: =Model!D739 -> 2.8323072 | F39: =G39-E39 -> 1.6855227 | G39: =Model!H743 -> 4.5178299
D40: DCF - Terminal Multiple | E40: =Model!D750 -> 2.5816457 | F40: =G40-E40 -> 1.9964775 | G40: =Model!H754 -> 4.5781231
D41: 52 Week High/Low | E41: =Inputs!L107 -> 3.2 | F41: =G41-E41 -> 1.8 | G41: =Inputs!L106 -> 5
D42: ="Average Valuation: "&TEXT(E42,"$0.00") -> Average Valuation: $3.93 | E42: =AVERAGE(E37:E40,G37:G40) -> 3.9342386

Sheet Model-R
B3: Revenue Schedule
B5: All figures in USD thousands unless stated | F5: =G5-1 -> 2020 | G5: =H5-1 -> 2021 | H5: =I5-1 -> 2022 | I5: =Inputs!F105 -> 2023 | J5: =I5+1 -> 2024 | K5: =J5+1 -> 2025 | L5: =K5+1 -> 2026 | M5: =L5+1 -> 2027 | N5: Term
B6: {=CONCATENATE("Model Running: ",INDEX(Inputs!$B$12:$B$14,Inputs!$D$7)," Drivers")} -> Model Running: Base Case Drivers
B8: Days in Period | C8: =Inputs!F108 -> 365 | F8: 365 | G8: 365 | H8: 365 | I8: =$C$8 -> 365 | J8: =$C$8 -> 365 | K8: =$C$8 -> 365 | L8: =$C$8 -> 365 | M8: =$C$8 -> 365 | N8: =$C$8 -> 365
B9: Plant Capacity | C9: =Inputs!#REF! -> #REF!
B12: OPERATIONS
Q13: Learner | R13: Correct | S13: Compare
B14: Sales Volume Growth | G14: =G16/F16-1 -> 0.019650655 | H14: =H16/G16-1 -> 0.0206995 | I14: =Inputs!G10 -> 0.03 | J14: =Inputs!H10 -> 0.02 | K14: =Inputs!I10 -> 0.02 | L14: =Inputs!J10 -> 0.015 | M14: =Inputs!K10 -> 0.015 | N14: =Inputs!L10 -> 0.01 | Q14: =SUM(Model!#REF!) -> #REF! | R14: =SUM(Inputs!G10:L10) -> 0.11 | S14: =IF(ISBLANK(Model!#REF!),0,IF(Q14=R14,1,0)) -> #REF!
B16: Sales Volume | D16: (Units/Day) | F16: 1374 | G16: 1401 | H16: 1430 | I16: =H16*(1+I14) -> 1472.9 | J16: =I16*(1+J14) -> 1502.358 | K16: =J16*(1+K14) -> 1532.4052 | L16: =K16*(1+L14) -> 1555.3912 | M16: =L16*(1+M14) -> 1578.7221 | N16: =M16*(1+N14) -> 1594.5093
B17: Plant Capacity | D17: (Units/Day) | F17: 1600 | G17: 1600 | H17: 1600 | I17: =$C$9 -> #REF! | J17: =$C$9 -> #REF! | K17: =$C$9 -> #REF! | L17: =$C$9 -> #REF! | M17: =$C$9 -> #REF! | N17: =$C$9 -> #REF!
B18: Operational Efficiency | F18: =F16/F17 -> 0.85875 | G18: =G16/G17 -> 0.875625 | H18: =H16/H17 -> 0.89375 | I18: =I16/I17 -> #REF! | J18: =J16/J17 -> #REF! | K18: =K16/K17 -> #REF! | L18: =L16/L17 -> #REF! | M18: =M16/M17 -> #REF! | N18: =N16/N17 -> #REF!
B23: VOLUME
B25: Days in Period | F25: =F8 -> 365 | G25: =G8 -> 365 | H25: =H8 -> 365 | I25: =I8 -> 365 | J25: =J8 -> 365 | K25: =K8 -> 365 | L25: =L8 -> 365 | M25: =M8 -> 365 | N25: =N8 -> 365
B26: Sales Volume | D26: (Units/Day) | F26: =F16 -> 1374 | G26: =G16 -> 1401 | H26: =H16 -> 1430 | I26: =I16 -> 1472.9 | J26: =J16 -> 1502.358 | K26: =K16 -> 1532.4052 | L26: =L16 -> 1555.3912 | M26: =M16 -> 1578.7221 | N26: =N16 -> 1594.5093
B27: Sales Volume | D27: (Units) | F27: =F26*F25 -> 501510 | G27: =G26*G25 -> 511365 | H27: =H26*H25 -> 521950 | I27: =I26*I25 -> 537608.5 | J27: =J26*J25 -> 548360.67 | K27: =K26*K25 -> 559327.88 | L27: =L26*L25 -> 567717.8 | M27: =M26*M25 -> 576233.57 | N27: =N26*N25 -> 581995.9
B30: PRICING
Q31: Learner | R31: Correct | S31: Compare
B32: Pricing Increases | G32: =G33/F33-1 -> 0.017013416 | H32: =H33/G33-1 -> 0.021030494 | I32: =Inputs!G17 -> 0.035 | J32: =Inputs!H17 -> 0.03 | K32: =Inputs!I17 -> 0.03 | L32: =Inputs!J17 -> 0.025 | M32: =Inputs!K17 -> 0.025 | N32: =Inputs!L17 -> 0.015 | Q32: =SUM(Model!#REF!) -> #REF! | R32: =SUM(Inputs!G17:L17) -> 0.16 | S32: =IF(ISBLANK(Model!#REF!),0,IF(Q32=R32,1,0)) -> #REF!
B33: Unit Price | D33: (USD/Unit) | F33: 102.86 | G33: 104.61 | H33: 106.81 | I33: =H33*(1+I32) -> 110.54835 | J33: =I33*(1+J32) -> 113.8648 | K33: =J33*(1+K32) -> 117.28074 | L33: =K33*(1+L32) -> 120.21276 | M33: =L33*(1+M32) -> 123.21808 | N33: =M33*(1+N32) -> 125.06635
B36: REVENUE
B38: Sales Volume | D38: (Units) | F38: =F27 -> 501510 | G38: =G27 -> 511365 | H38: =H27 -> 521950 | I38: =I27 -> 537608.5 | J38: =J27 -> 548360.67 | K38: =K27 -> 559327.88 | L38: =L27 -> 567717.8 | M38: =M27 -> 576233.57 | N38: =N27 -> 581995.9
B39: Sales Price | D39: (USD/Unit) | F39: =F33 -> 102.86 | G39: =G33 -> 104.61 | H39: =H33 -> 106.81 | I39: =I33 -> 110.54835 | J39: =J33 -> 113.8648 | K39: =K33 -> 117.28074 | L39: =L33 -> 120.21276 | M39: =M33 -> 123.21808 | N39: =N33 -> 125.06635
B40: Revenue | F40: =F38*F39/1000 -> 51585.319 | G40: =G38*G39/1000 -> 53493.893 | H40: =H38*H39/1000 -> 55749.48 | I40: =I38*I39/1000 -> 59431.733 | J40: =J38*J39/1000 -> 62438.978 | K40: =K38*K39/1000 -> 65598.391 | L40: =L38*L39/1000 -> 68246.926 | M40: =M38*M39/1000 -> 71002.395 | N40: =N38*N39/1000 -> 72788.105
B43: Operational Capacity Exceeded? | F43: =IF(F18>=1,1,0) -> 0 | G43: =IF(G18>=1,1,0) -> 0 | H43: =IF(H18>=1,1,0) -> 0 | I43: =IF(I18>=1,1,0) -> #REF! | J43: =IF(J18>=1,1,0) -> #REF! | K43: =IF(K18>=1,1,0) -> #REF! | L43: =IF(L18>=1,1,0) -> #REF! | M43: =IF(M18>=1,1,0) -> #REF! | N43: =IF(N18>=1,1,0) -> #REF! | S43: =IF(SUM(S13:S40)=2,"COMPLETE","") -> #REF!
B47: Cost Schedule
B49: All figures in USD thousands unless stated | F49: =F$5 -> 2020 | G49: =G$5 -> 2021 | H49: =H$5 -> 2022 | I49: =I$5 -> 2023 | J49: =J$5 -> 2024 | K49: =K$5 -> 2025 | L49: =L$5 -> 2026 | M49: =M$5 -> 2027 | N49: =N$5 -> Term
B50: =$B$6 -> Model Running: Base Case Drivers
B52: Sales Volume | F52: =F38 -> 501510 | G52: =G38 -> 511365 | H52: =H38 -> 521950 | I52: =I38 -> 537608.5 | J52: =J38 -> 548360.67 | K52: =K38 -> 559327.88 | L52: =L38 -> 567717.8 | M52: =M38 -> 576233.57 | N52: =N38 -> 581995.9 | Q52: Learner | R52: Correct | S52: Compare
B53: Inflation | F53: 0.024 | G53: 0.022 | H53: 0.023 | I53: =Inputs!G31 -> 0.035 | J53: =Inputs!H31 -> 0.03 | K53: =Inputs!I31 -> 0.03 | L53: =Inputs!J31 -> 0.025 | M53: =Inputs!K31 -> 0.025 | N53: =Inputs!L31 -> 0.015 | Q53: =SUM(Model!I7:N7) -> 0.16 | R53: =SUM(I53:N53) -> 0.16 | S53: =IF(ISBLANK(Model!I7),0,IF(Q53=R53,1,0)) -> 1
B55: VARIABLE COSTS
B57: Materials | D57: (USD/Unit) | F57: 9.51 | G57: 9.72 | H57: 9.91 | I57: =H57*(1+I$53) -> 10.25685 | J57: =I57*(1+J$53) -> 10.564556 | K57: =J57*(1+K$53) -> 10.881492 | L57: =K57*(1+L$53) -> 11.153529 | M57: =L57*(1+M$53) -> 11.432368 | N57: =M57*(1+N$53) -> 11.603853
B58: Packaging | D58: (USD/Unit) | F58: 0.82 | G58: 0.84 | H58: 0.86 | I58: =H58*(1+I$53) -> 0.8901 | J58: =I58*(1+J$53) -> 0.916803 | K58: =J58*(1+K$53) -> 0.94430709 | L58: =K58*(1+L$53) -> 0.96791477 | M58: =L58*(1+M$53) -> 0.99211264 | N58: =M58*(1+N$53) -> 1.0069943
B59: Transportation | D59: (USD/Unit) | F59: 1.54 | G59: 1.58 | H59: 1.62 | I59: =H59*(1+I$53) -> 1.6767 | J59: =I59*(1+J$53) -> 1.727001 | K59: =J59*(1+K$53) -> 1.778811 | L59: =K59*(1+L$53) -> 1.8232813 | M59: =L59*(1+M$53) -> 1.8688633 | N59: =M59*(1+N$53) -> 1.8968963
B60: Subtotal | F60: =SUM(F57:F59) -> 11.87 | G60: =SUM(G57:G59) -> 12.14 | H60: =SUM(H57:H59) -> 12.39 | I60: =SUM(I57:I59) -> 12.82365 | J60: =SUM(J57:J59) -> 13.20836 | K60: =SUM(K57:K59) -> 13.60461 | L60: =SUM(L57:L59) -> 13.944726 | M60: =SUM(M57:M59) -> 14.293344 | N60: =SUM(N57:N59) -> 14.507744
B62: Materials | F62: =F57*F$52/1000 -> 4769.3601 | G62: =G57*G$52/1000 -> 4970.4678 | H62: =H57*H$52/1000 -> 5172.5245 | I62: =I57*I$52/1000 -> 5514.1697 | J62: =J57*J$52/1000 -> 5793.1867 | K62: =K57*K$52/1000 -> 6086.322 | L62: =L57*L$52/1000 -> 6332.0572 | M62: =M57*M$52/1000 -> 6587.714 | N62: =N57*N$52/1000 -> 6753.395
B63: Packaging | F63: =F58*F$52/1000 -> 411.2382 | G63: =G58*G$52/1000 -> 429.5466 | H63: =H58*H$52/1000 -> 448.877 | I63: =I58*I$52/1000 -> 478.52533 | J63: =J58*J$52/1000 -> 502.73871 | K63: =K58*K$52/1000 -> 528.17729 | L63: =L58*L$52/1000 -> 549.50244 | M63: =M58*M$52/1000 -> 571.68861 | N63: =N58*N$52/1000 -> 586.06657
B64: Transportation | F64: =F59*F$52/1000 -> 772.3254 | G64: =G59*G$52/1000 -> 807.9567 | H64: =H59*H$52/1000 -> 845.559 | I64: =I59*I$52/1000 -> 901.40817 | J64: =J59*J$52/1000 -> 947.01943 | K64: =K59*K$52/1000 -> 994.93861 | L64: =L59*L$52/1000 -> 1035.1093 | M64: =M59*M$52/1000 -> 1076.9018 | N64: =N59*N$52/1000 -> 1103.9859
B65: Subtotal | F65: =SUM(F62:F64) -> 5952.9237 | G65: =SUM(G62:G64) -> 6207.9711 | H65: =SUM(H62:H64) -> 6466.9605 | I65: =SUM(I62:I64) -> 6894.1032 | J65: =SUM(J62:J64) -> 7242.9449 | K65: =SUM(K62:K64) -> 7609.4379 | L65: =SUM(L62:L64) -> 7916.6689 | M65: =SUM(M62:M64) -> 8236.3044 | N65: =SUM(N62:N64) -> 8443.4475
B68: FIXED COSTS
B70: Labor | D70: (USD/Unit) | F70: =(F75*1000)/F$52 -> 31.165879 | G70: =(G75*1000)/G$52 -> 31.236006 | H70: =(H75*1000)/H$52 -> 31.307597 | I70: =(I75*1000)/I$52 -> 31.459575 | J70: =(J75*1000)/J$52 -> 31.768002 | K70: =(K75*1000)/K$52 -> 32.079453 | L70: =(L75*1000)/L$52 -> 32.395507 | M70: =(M75*1000)/M$52 -> 32.714675 | N70: =(N75*1000)/N$52 -> 32.876628
...
